Workbook

Sheet 1. README & Legend
B1: AI STYLIST / DIGITAL WARDROBE - COMPETITIVE INTELLIGENCE FRAMEWORK
B2: Phase 1 deliverable - Market Map & Master Feature Taxonomy
C5: HOW TO READ THIS WORKBOOK
B6: Version | C6: 1.0
B7: Compiled | C7: 26 August 2026
B8: Status | C8: LIVING DOCUMENT - update in place rather than starting over. Add new features as rows; split a row into two when two apparently identical features turn out to be materially different.
C10: SHEET GUIDE
B11: 2. Competitive Universe | C11: Direct / Adjacent / Emerging products with company, geography, model, scale and an EVIDENCE CONFIDENCE column.
B12: 3. Product Archetypes | C12: Nine archetypes and the migration pattern between them.
B13: 4. Jobs To Be Done | C13: Stated job vs UNDERLYING job for each product, plus three structural insights.
B14: 5. Feature Matrix | C14: THE KEY DELIVERABLE. ~330 granular capabilities x 9 products. Filterable by Category. Auto-calculated coverage columns on the right.
B15: 6. Coverage Summary | C15: Formula-driven roll-up: how many capabilities each product has, by category. Nothing is hardcoded here.
B16: 7. Sophistication Scores | C16: 1-4 depth ratings for major features, where 'has the feature' and 'is good at it' diverge most.
B17: 8. AI Intelligence Layer | C17: What is ACTUALLY under the hood, separated from the marketing label.
B18: 9. Table Stakes vs Diff. | C18: Classification of every capability into Table Stakes / Differentiator / Emerging.
B19: 10. Research Gaps | C19: 20 prioritised open questions with a method for closing each. Work the Tier 1 list first.
B20: 11. Sources & Reliability | C20: Every source used, what it was used for, and how much to trust it.
C22: LEGEND - FEATURE MATRIX SYMBOLS
B23: ✓ | C23: Clearly available
B24: ◐ | C24: Partially available / limited / gated behind a paywall
B25: — | C25: Not available
B26: ? | C26: Unclear - requires verification
B27: Suffix: AI | C27: Explicitly AI-powered (e.g. ✓AI)
B28: Suffix: H | C28: Human-powered (e.g. ✓H)
B29: Suffix: man | C29: Manual only (e.g. ✓man - Stylebook)
B30: Suffix: paid | C30: Available but paywalled
B31: Suffix: roadmap | C31: Announced or funded but not yet shipped
C33: LEGEND - SOPHISTICATION SCORES (Sheet 7)
B34: 1 | C34: Basic implementation
B35: 2 | C35: Moderate
B36: 3 | C36: Sophisticated
B37: 4 | C37: Highly differentiated
B38: ? | C38: Insufficient information
B39: n/a | C39: Product does not attempt this capability
C41: COLUMN CODES
B42: WHE / ACL / IND / CLA / STB | C42: Whering / Acloset / Indyx / Cladwell / Stylebook
B43: ALT / PRO / PUR / VES | C43: Alta / Pronti / Pureple / Vesta Wardrobe
B44: Referenced in Notes | C44: GW = GetWardrobe, SD = Style DNA, SYW = Save Your Wardrobe, CBY = Combyne, SF = Stitch Fix
C46: *** EVIDENCE CAVEAT - READ THIS ***
B47: Where the marks come from | C47: Unless a Note says otherwise, marks derive from App Store / Google Play listings, official websites and release notes - i.e. VENDOR MARKETING COPY. This systematically OVERSTATES capability, especially for anything labelled 'AI'.
...

Sheet 2. Competitive Universe
A1: COMPETITIVE UNIVERSE
A2: A = Direct competitors | B = Adjacent | C = Emerging. 'Evidence confidence' states how much to trust each row.
A4: Tier | B4: Product | C4: Company | D4: Geography | E4: Launch | F4: Core proposition | G4: Primary user | H4: Product archetype | I4: Key differentiator | J4: Business model | K4: Platforms | L4: Approx. scale / funding | M4: Evidence confidence
A5: A. Direct | B5: Whering | C5: Whering Ltd | D5: London, UK | E5: 2020-21 (sources disagree) | F5: Digital wardrobe + social styling + sustainability | G5: Gen Z women, sustainability-leaning | H5: Digital closet first, drifting to AI + resale | I5: Scale + community + circularity brand | J5: Freemium; resale/affiliate ambitions | K5: iOS, Android, Web | L5: 10M users (Jul 2026); $7M seed led by eBay Ventures + Google AI Futures Fund; ~$14M total; ~14 staff (Tracxn, mid-2024) | M5: High (WWD, Tech.eu, TheIndustry.fashion)
A6: A. Direct | B6: Acloset | C6: Looko Inc. | D6: Seoul, South Korea | E6: 2020 | F6: AI fashion assistant: auto-digitisation + chat stylist | G6: Global, 8+ languages | H6: AI stylist first (on a closet base) | I6: Best-in-class ingestion: Gmail receipts, retailer import, multi-item photo parsing | J6: Freemium (100-item free cap); sub tiers; ad-supported tier | K6: iOS, Android | L6: Claims range 4M / 7M / 8M users - INCONSISTENT. Funding DISPUTED: $2.57M (CB Insights) vs $63M Series C (startuphub.ai, low confidence) | M6: Medium (features high, scale/funding low)
A7: A. Direct | B7: Indyx | C7: Indyx Inc. | D7: USA | E7: ~2022 | F7: Free best-in-class closet + paid human stylist Lookbooks | G7: US women 25-45, style-invested | H7: Human stylist first, on a closet substrate | I7: Real stylists + in-home professional cataloguing ('Archivist') | J7: Free core; 'Insider' sub ~$9/mo; paid styling services | K7: iOS, Android | L7: Not publicly disclosed | M7: High on features (detailed store listing + 2 independent reviews)
A8: A. Direct | B8: Cladwell | C8: The Cladwell Group, Inc. | D8: Cincinnati, USA | E8: 2016 | F8: Capsule wardrobe + daily outfit prescription | G8: Intentional-living / minimalist women | H8: Wardrobe philosophy first | I8: Capsule methodology + course content | J8: CONFLICTING: free-for-life claims vs $60-79/yr | K8: iOS, Android | L8: 1M+ downloads; company claims 13M items catalogued, 100M outfits suggested, 3.5M styling sessions | M8: Medium (pricing and calendar features contradict across sources)
A9: A. Direct | B9: Stylebook | C9: Left Brain / Right Brain LLC | D9: USA | E9: 2010 | F9: Manual, exhaustive wardrobe database + analytics | G9: Detail-obsessed power users | H9: Wardrobe analytics first | I9: Depth of manual control; one-time price; NO AI | J9: One-time purchase (~$4.99-5.99) | K9: iOS ONLY | L9: Long tail; the category's original product | M9: High (consistent across many independent reviews)
A10: A. Direct | B10: Alta | C10: Alta | D10: New York, USA (moved from SF) | E10: 2025 | F10: AI styling agent + avatar try-on + agentic shopping | G10: Fashion-engaged US women | H10: AI stylist + shopping first | I10: 12+ in-house-trained fashion-specific generative models; avatar try-on mixing owned + new items | J10: Affiliate/commerce; 4,000+ brand partnerships; emerging enterprise/white-label | K10: iOS (+ embedded brand experience) | L10: $11M seed led by Menlo Ventures. Investors incl. Aglae (LVMH-linked), Anthology Fund, Karlie Kloss, Jasmine Tookes, Jenny Fleiss, Tony Xu. CFDA partnership; Marie Kondo APAC collab | M10: High on funding/press; LOW on verified product depth
A11: A. Direct | B11: Pronti | C11: Pronti AI Inc. | D11: Waterloo, Canada | E11: 2021 | F11: Conversational AI stylist grounded in your real closet | G11: Women + men + non-binary (5-point gender slider) | H11: AI fashion companion | I11: 'PAI' chat stylist explicitly grounded in the user's own items; Shopify app for retailers | J11: Free; affiliate + ads + premium + AI chat credits | K11: iOS, Android, Web | L11: Viral TikTok moment (2M+ views); briefly #2 App Store Lifestyle (CA) | M11: High on features (detailed release notes); low on scale
A12: A. Direct | B12: Pureple | C12: Iceclip / ICECLIP LLC | D12: USA | E12: 2013 | F12: Outfit planner + virtual closet + AI try-on | G12: Broad, value-conscious | H12: Outfit planner first | I12: Longevity + breadth; AI try-on on a model | J12: Freemium; aggressive sub ($6.99/wk - $89.99/yr); heavy ads | K12: iOS, Android | L12: Claims 3M+ users; ~2.5M+ Play downloads per third party | M12: Medium (pricing varies by source and date)
A13: A. Direct | B13: GetWardrobe | C13: 3Botinka LLC | D13: Eastern Europe origin | E13: 2013 | F13: Cross-platform closet + AI outfit generator + family wardrobes | G13: Data-inclined planners, families | H13: Digital closet + planner | I13: Family wardrobes; stylist client dashboard; iOS/Android/macOS/WEB | J13: Freemium (100 items free) + Premium sub | K13: iOS, Android, macOS, Web | L13: Claims 3M+ users across 39 countries; ~4,174 iOS + ~4,848 Play ratings | M13: Medium-High
A14: A. Direct | B14: Vesta Wardrobe | C14: Meg Tech Inc. | D14: USA | E14: 2025 | F14: AI stylist + style archetype + calendar | G14: Early adopters | H14: AI stylist first (thin) | I14: Style-archetype framing; swipe-based taste learning | J14: Freemium | K14: iOS | L14: VERY SMALL. NAME COLLISION WARNING: 'Vesta', 'Vestia', 'Vestra', 'Vesta AI' are four different products | M14: Low-Medium (few reviews; AI quality disputed by reviewers)
A15: A. Direct | B15: Smart Closet | C15: Various listings | D15: Korea / US | E15: ~2017 | F15: Closet + trending outfits + shop | G15: Broad | H15: Digital closet + shopping | I15: Shopping-adjacent closet | J15: Freemium / one-time | K15: iOS, Android | L15: Widely described as stagnant / unmaintained in independent reviews | M15: Low
... A36: C. Emerging | B36: Libre Closet | C36: Open source community | D36: Global | E36: ~2025 | F36: Free, open-source, Docker-deployable wardrobe manager | G36: Self-hosters | H36: Digital closet first | I36: Signal that the DATA MODEL itself has no defensible value | J36: Free / open source | K36: Self-host, Docker, Web | L36: Small | M36: MEDIUM as a signal

Sheet 3. Product Archetypes
A1: PRODUCT ARCHETYPE MAP
A2: Products can occupy more than one archetype. What matters is what each is fundamentally trying to become for the user.
A4: # | B4: Archetype | C4: What it fundamentally wants to become | D4: Products | E4: Core metric it optimises
A5: 1 | B5: Digital closet first | C5: The definitive record of what you own | D5: Stylebook, GetWardrobe, Whering, Acloset, Save Your Wardrobe, Fits | E5: Items digitised; closet completeness
A6: 2 | B6: Wardrobe analytics first | C6: The accountant of your wardrobe | D6: Stylebook, Indyx (Insider tier), GetWardrobe | E6: Cost-per-wear, utilisation %, wardrobe value
A7: 3 | B7: Outfit planner first | C7: Your morning-routine calendar | D7: Pureple, Cladwell, GetWardrobe, Fits | E7: Outfits planned / logged per week
A8: 4 | B8: AI stylist first | C8: The thing that decides FOR you | D8: Alta, Acloset, Pronti, Vesta, Cladwell (Ask Cladwell) | E8: Recommendation acceptance rate
A9: 5 | B9: Human stylist first | C9: Access to taste you do not have | D9: Wishi, Stitch Fix, Indyx (Lookbooks) | E9: Session / box conversion; stylist NPS
A10: 6 | B10: Shopping / commerce first | C10: A better way to buy clothes | D10: Alta, Phia, Daydream, Glance AI, Smart Closet, Style DNA | E10: GMV, affiliate revenue, return rate
A11: 7 | B11: Virtual try-on first | C11: The mirror that precedes purchase | D11: Doji, Aiuta, Google VTO, Glance AI, Stitch Fix Vision | E11: Try-ons generated; purchase lift
A12: 8 | B12: Social fashion first | C12: A place to perform and be seen | D12: Combyne, Whering (community), Outflik, Indyx (Social Styling) | E12: DAU, posts, follows, feedback loops
A13: 9 | B13: Sustainability / circular first | C13: The infrastructure that keeps clothes alive | D13: Save Your Wardrobe, Whering, Cladwell (capsule) | E13: Garment lifespan, repairs, resale
B16: MIGRATION PATTERN (the strategic story of the category):
B17: Digital closet first -> AI stylist first -> Shopping / commerce first
B18: | |
B19: +-> Sustainability / circular, or B2B infrastructure <-+
B21: Nearly everyone starts at 'digital closet', discovers the retention problem, adds 'AI stylist',
B22: discovers subscriptions do not cover CAC, and drifts toward commerce, B2B or circularity.
B23: Whering (eBay Ventures money, resale integrations, try-on roadmap), Alta (agentic shopping +
B24: enterprise identity layer), Save Your Wardrobe (full B2B pivot) and Pronti (affiliate + Shopify app)
B25: are four different resolutions of the same pressure.
B26: Stylebook is the notable refusenik: one-time fee, no AI, no commerce, iOS-only, since 2010.

Sheet 4. Jobs To Be Done
A1: THE USER JOB TO BE DONE
A2: Stripped of marketing language. Stated job and underlying job diverge sharply - that divergence is the point.
A4: Product | B4: Stated job ('why do I open this app?') | C4: UNDERLYING job | D4: Trigger moment | E4: Emotional payload
A5: Whering | B5: Show me outfits from what I own | C5: Give me permission to NOT buy something. Also: let me be seen as someone with taste and values | D5: Standing at the closet; also mid-impulse-purchase | E5: Guilt relief; identity signalling
A6: Acloset | B6: Tell me what to wear today | C6: Make the decision so I can stop thinking about it | D6: Weekday morning | E6: Decision-fatigue relief
A7: Indyx | B7: Organise my wardrobe properly | C7: I want a professional to tell me I am doing this right. The app is the substrate; the stylist is the product | D7: Seasonal reset; life transition | E7: Reassurance; competence
A8: Cladwell | B8: Simplify my wardrobe | C8: I want to become a different kind of person - someone who owns less and is calmer | D8: Post-declutter; New Year | E8: Moral / identity transformation
A9: Stylebook | B9: Track my wardrobe | C9: I want to feel in control of an expensive, chaotic part of my life. The cataloguing IS the reward, not a cost | D9: Sunday afternoon; travel prep | E9: Mastery; order
A10: Alta | B10: Style me and show me on me | C10: Let me see a better version of myself before I commit money | D10: Pre-purchase; pre-event | E10: Aspiration; risk reduction
A11: Pronti | B11: Ask my closet what to wear | C11: I want a second opinion I do not have to be embarrassed in front of | D11: Any moment of doubt | E11: Private validation
A12: Pureple | B12: Plan my outfits | C12: Reduce the number of mornings I get it wrong | D12: Weekly planning; packing | E12: Preparedness
A13: Style DNA | B13: What colours suit me? | C13: Tell me the rules so I can stop guessing forever | D13: Post-haircut; pre-wardrobe-overhaul | E13: Certainty; permission
A14: Combyne | B14: Make outfits and share them | C14: Give me a low-stakes creative outlet and an audience. THIS IS A BOREDOM PRODUCT, NOT A PROBLEM PRODUCT | D14: Idle time | E14: Play; belonging; status
A15: Wishi / Stitch Fix | B15: Get styled | C15: Outsource a domain I have decided not to master | D15: Wardrobe crisis; job change | E15: Delegation
... A18: ChatGPT | B18: Does this outfit work? | C18: Answer my exact question without me building anything first | D18: Any | E18: Zero-friction competence
A21: THREE JTBD INSIGHTS THAT SHOULD SHAPE EVERYTHING DOWNSTREAM:
A23: 1. 'I do not know what to wear' and 'I want to organise my wardrobe' are DIFFERENT CUSTOMERS, not different features.
A24: Stylebook users ENJOY cataloguing; Acloset users RESENT it. Products serving both end up with a setup cost only
A25: the organisers tolerate and an AI only the deciders need.
A27: 2. FREQUENCY ASYMMETRY. The 'what do I wear' job fires ~365x/year but is worth cents. The 'what should I buy' job
A28: fires ~10-30x/year but is worth dollars. Everyone monetises the low-frequency job with revenue earned from the
A29: high-frequency one. This is exactly why the commerce drift happens - and why DAILY engagement is the strategic
A30: asset even when it is not the revenue line.
A32: 3. The strongest engagement product in the category (Combyne, 10M+ Gen Z) DOES NOT DO THE JOB AT ALL.
A33: It serves boredom, not dressing. That is either a warning or an opportunity, depending on your thesis.

Sheet 5. Feature Matrix
A1: MASTER FEATURE CHECKLIST
A2: Filterable by Category. Rows where EVERY product is — are deliberate: they are the theoretical-universe capabilities nobody has built. Coverage columns are live formulas. See Sheet 1 for the legend and the evidence caveat.
A4: # | B4: Category | C4: Capability | D4: WHE | E4: ACL | F4: IND | G4: CLA | H4: STB | I4: ALT | J4: PRO | K4: PUR | L4: VES | M4: Full (✓) | N4: Partial (◐) | O4: Absent (—) | P4: Unclear (?) | Q4: Coverage % | R4: Notes / evidence
A5: 1 | B5: A. Discovery / Acquisition | C5: App Store / Play organic search | D5: ✓ | E5: ✓ | F5: ✓ | G5: ✓ | H5: ◐ | I5: ✓ | J5: ✓ | K5: ✓ | L5: ✓ | M5: =SUMPRODUCT(--ISNUMBER(SEARCH("✓",D5:L5))) -> 8 | N5: =SUMPRODUCT(--ISNUMBER(SEARCH("◐",D5:L5))) -> 1 | O5: =SUMPRODUCT(--ISNUMBER(SEARCH("—",D5:L5))) -> 0 | P5: =9-M5-N5-O5 -> 0 | Q5: =(M5+0.5*N5)/9 -> 0.94444444 | R5: Stylebook is iOS-only. ASO keyword stuffing is universal.
A6: 2 | B6: A. Discovery / Acquisition | C6: TikTok / Reels organic virality | D6: ✓ | E6: ✓ | F6: ✓ | G6: ◐ | H6: — | I6: ✓ | J6: ✓ | K6: ◐ | L6: ? | M6: =SUMPRODUCT(--ISNUMBER(SEARCH("✓",D6:L6))) -> 5 | N6: =SUMPRODUCT(--ISNUMBER(SEARCH("◐",D6:L6))) -> 2 | O6: =SUMPRODUCT(--ISNUMBER(SEARCH("—",D6:L6))) -> 1 | P6: =9-M6-N6-O6 -> 1 | Q6: =(M6+0.5*N6)/9 -> 0.66666667 | R6: Pronti had a single TikTok hit >2M views that crashed the app and forced a waitlist.
A7: 3 | B7: A. Discovery / Acquisition | C7: 'Clueless closet' cultural hook | D7: ✓ | E7: ◐ | F7: — | G7: ✓ | H7: — | I7: ✓ | J7: ✓ | K7: — | L7: — | M7: =SUMPRODUCT(--ISNUMBER(SEARCH("✓",D7:L7))) -> 4 | N7: =SUMPRODUCT(--ISNUMBER(SEARCH("◐",D7:L7))) -> 1 | O7: =SUMPRODUCT(--ISNUMBER(SEARCH("—",D7:L7))) -> 4 | P7: =9-M7-N7-O7 -> 0 | Q7: =(M7+0.5*N7)/9 -> 0.5 | R7: The category's shared origin myth; Alta, Whering, Cladwell and Pronti all invoke it.
A8: 4 | B8: A. Discovery / Acquisition | C8: Influencer / creator partnerships | D8: ✓ | E8: ✓ | F8: ✓ | G8: ◐ | H8: — | I8: ✓ | J8: ◐ | K8: — | L8: — | M8: =SUMPRODUCT(--ISNUMBER(SEARCH("✓",D8:L8))) -> 4 | N8: =SUMPRODUCT(--ISNUMBER(SEARCH("◐",D8:L8))) -> 2 | O8: =SUMPRODUCT(--ISNUMBER(SEARCH("—",D8:L8))) -> 3 | P8: =9-M8-N8-O8 -> 0 | Q8: =(M8+0.5*N8)/9 -> 0.55555556 | R8: Alta: Karlie Kloss, Jasmine Tookes as investor-advocates.
A9: 5 | B9: A. Discovery / Acquisition | C9: Celebrity / expert credibility anchor | D9: — | E9: — | F9: ◐H | G9: — | H9: — | I9: ✓H | J9: — | K9: — | L9: — | M9: =SUMPRODUCT(--ISNUMBER(SEARCH("✓",D9:L9))) -> 1 | N9: =SUMPRODUCT(--ISNUMBER(SEARCH("◐",D9:L9))) -> 1 | O9: =SUMPRODUCT(--ISNUMBER(SEARCH("—",D9:L9))) -> 7 | P9: =9-M9-N9-O9 -> 0 | Q9: =(M9+0.5*N9)/9 -> 0.16666667 | R9: Alta: Meredith Koop (Michelle Obama's stylist) trained models. Indyx: staff stylists. Style DNA: unnamed 'world-renowned image consultants'.
A10: 6 | B10: A. Discovery / Acquisition | C10: Institutional / industry endorsement | D10: — | E10: — | F10: — | G10: — | H10: — | I10: ✓ | J10: — | K10: — | L10: — | M10: =SUMPRODUCT(--ISNUMBER(SEARCH("✓",D10:L10))) -> 1 | N10: =SUMPRODUCT(--ISNUMBER(SEARCH("◐",D10:L10))) -> 0 | O10: =SUMPRODUCT(--ISNUMBER(SEARCH("—",D10:L10))) -> 8 | P10: =9-M10-N10-O10 -> 0 | Q10: =(M10+0.5*N10)/9 -> 0.11111111 | R10: Alta-CFDA partnership; Marie Kondo (APAC). Save Your Wardrobe: LVMH Innovation Award 2023.
A11: 7 | B11: A. Discovery / Acquisition | C11: In-app referral / invite mechanic | D11: ✓ | E11: ✓ | F11: ✓ | G11: ? | H11: — | I11: ? | J11: ✓ | K11: ✓ | L11: ? | M11: =SUMPRODUCT(--ISNUMBER(SEARCH("✓",D11:L11))) -> 5 | N11: =SUMPRODUCT(--ISNUMBER(SEARCH("◐",D11:L11))) -> 0 | O11: =SUMPRODUCT(--ISNUMBER(SEARCH("—",D11:L11))) -> 1 | P11: =9-M11-N11-O11 -> 3 | Q11: =(M11+0.5*N11)/9 -> 0.55555556 | R11: Pronti: earn AI chat credits via referral - the only credit-linked referral found.
A12: 8 | B12: A. Discovery / Acquisition | C12: Friend-graph import | D12: ◐ | E12: ◐ | F12: ✓ | G12: — | H12: — | I12: — | J12: — | K12: ◐ | L12: — | M12: =SUMPRODUCT(--ISNUMBER(SEARCH("✓",D12:L12))) -> 1 | N12: =SUMPRODUCT(--ISNUMBER(SEARCH("◐",D12:L12))) -> 3 | O12: =SUMPRODUCT(--ISNUMBER(SEARCH("—",D12:L12))) -> 5 | P12: =9-M12-N12-O12 -> 0 | Q12: =(M12+0.5*N12)/9 -> 0.27777778 | R12: Indyx closet-sharing links are the strongest viral loop in the direct set.
A13: 9 | B13: A. Discovery / Acquisition | C13: Public / shareable closet or lookbook link | D13: ◐ | E13: ✓ | F13: ✓ | G13: ◐ | H13: — | I13: ? | J13: ✓ | K13: ✓ | L13: ◐ | M13: =SUMPRODUCT(--ISNUMBER(SEARCH("✓",D13:L13))) -> 4 | N13: =SUMPRODUCT(--ISNUMBER(SEARCH("◐",D13:L13))) -> 3 | O13: =SUMPRODUCT(--ISNUMBER(SEARCH("—",D13:L13))) -> 1 | P13: =9-M13-N13-O13 -> 1 | Q13: =(M13+0.5*N13)/9 -> 0.61111111 | R13: Indyx added shareable Collections links (2026).
A14: 10 | B14: A. Discovery / Acquisition | C14: Web / SEO content funnel | D14: ✓ | E14: ✓ | F14: ✓ | G14: ✓ | H14: ◐ | I14: ◐ | J14: ✓ | K14: ✓ | L14: — | M14: =SUMPRODUCT(--ISNUMBER(SEARCH("✓",D14:L14))) -> 6 | N14: =SUMPRODUCT(--ISNUMBER(SEARCH("◐",D14:L14))) -> 2 | O14: =SUMPRODUCT(--ISNUMBER(SEARCH("—",D14:L14))) -> 1 | P14: =9-M14-N14-O14 -> 0 | Q14: =(M14+0.5*N14)/9 -> 0.77777778 | R14: Whering runs 'best wardrobe apps' content that ranks its own competitors.
A15: 11 | B15: A. Discovery / Acquisition | C15: Browser extension as acquisition surface | D15: ✓ | E15: ? | F15: — | G15: — | H15: — | I15: ? | J15: — | K15: — | L15: — | M15: =SUMPRODUCT(--ISNUMBER(SEARCH("✓",D15:L15))) -> 1 | N15: =SUMPRODUCT(--ISNUMBER(SEARCH("◐",D15:L15))) -> 0 | O15: =SUMPRODUCT(--ISNUMBER(SEARCH("—",D15:L15))) -> 6 | P15: =9-M15-N15-O15 -> 2 | Q15: =(M15+0.5*N15)/9 -> 0.11111111 | R15: Whering explicitly advertises a browser extension.
A16: 12 | B16: A. Discovery / Acquisition | C16: OEM / lock-screen / OS-level preinstall | D16: — | E16: — | F16: — | G16: — | H16: — | I16: — | J16: — | K16: — | L16: — | M16: =SUMPRODUCT(--ISNUMBER(SEARCH("✓",D16:L16))) -> 0 | N16: =SUMPRODUCT(--ISNUMBER(SEARCH("◐",D16:L16))) -> 0 | O16: =SUMPRODUCT(--ISNUMBER(SEARCH("—",D16:L16))) -> 9 | P16: =9-M16-N16-O16 -> 0 | Q16: =(M16+0.5*N16)/9 -> 0 | R16: GAP in direct set. Glance AI owns this (Samsung, Motorola, AT&T 'Lynk'). Structurally the cheapest distribution in the category.
... A18: 14 | B18: A. Discovery / Acquisition | C18: Waitlist / scarcity mechanic | D18: — | E18: — | F18: — | G18: — | H18: — | I18: ✓ | J18: ◐ | K18: — | L18: — | M18: =SUMPRODUCT(--ISNUMBER(SEARCH("✓",D18:L18))) -> 1 | N18: =SUMPRODUCT(--ISNUMBER(SEARCH("◐",D18:L18))) -> 1 | O18: =SUMPRODUCT(--ISNUMBER(SEARCH("—",D18:L18))) -> 7 | P18: =9-M18-N18-O18 -> 0 | Q18: =(M18+0.5*N18)/9 -> 0.16666667 | R18: Alta launched with a waitlist.
A19: 15 | B19: B. Onboarding - Input Capture | C19: Gender (binary) | D19: ✓ | E19: ✓ | F19: ✓ | G19: ✓ | H19: ✓ | I19: ✓ | J19: ✓ | K19: ✓ | L19: ✓ | M19: =SUMPRODUCT(--ISNUMBER(SEARCH("✓",D19:L19))) -> 9 | N19: =SUMPRODUCT(--ISNUMBER(SEARCH("◐",D19:L19))) -> 0 | O19: =SUMPRODUCT(--ISNUMBER(SEARCH("—",D19:L19))) -> 0 | P19: =9-M19-N19-O19 -> 0 | Q19: =(M19+0.5*N19)/9 -> 1
A20: 16 | B20: B. Onboarding - Input Capture | C20: Gender as spectrum / non-binary | D20: ? | E20: ? | F20: ? | G20: — | H20: — | I20: ? | J20: ✓ | K20: ? | L20: ? | M20: =SUMPRODUCT(--ISNUMBER(SEARCH("✓",D20:L20))) -> 1 | N20: =SUMPRODUCT(--ISNUMBER(SEARCH("◐",D20:L20))) -> 0 | O20: =SUMPRODUCT(--ISNUMBER(SEARCH("—",D20:L20))) -> 2 | P20: =9-M20-N20-O20 -> 6 | Q20: =(M20+0.5*N20)/9 -> 0.11111111 | R20: Pronti uses a 5-point gender slider - the only explicit non-binary handling found.
A21: 17 | B21: B. Onboarding - Input Capture | C21: Age / age band | D21: ✓ | E21: ✓ | F21: ? | G21: ✓ | H21: — | I21: ✓ | J21: ✓ | K21: ? | L21: ✓ | M21: =SUMPRODUCT(--ISNUMBER(SEARCH("✓",D21:L21))) -> 6 | N21: =SUMPRODUCT(--ISNUMBER(SEARCH("◐",D21:L21))) -> 0 | O21: =SUMPRODUCT(--ISNUMBER(SEARCH("—",D21:L21))) -> 1 | P21: =9-M21-N21-O21 -> 2 | Q21: =(M21+0.5*N21)/9 -> 0.66666667
A22: 18 | B22: B. Onboarding - Input Capture | C22: Location (for weather) | D22: ✓ | E22: ✓ | F22: ◐ | G22: ✓ | H22: ◐ | I22: ✓ | J22: ✓ | K22: ✓ | L22: ✓ | M22: =SUMPRODUCT(--ISNUMBER(SEARCH("✓",D22:L22))) -> 7 | N22: =SUMPRODUCT(--ISNUMBER(SEARCH("◐",D22:L22))) -> 2 | O22: =SUMPRODUCT(--ISNUMBER(SEARCH("—",D22:L22))) -> 0 | P22: =9-M22-N22-O22 -> 0 | Q22: =(M22+0.5*N22)/9 -> 0.88888889 | R22: GetWardrobe also.
A23: 19 | B23: B. Onboarding - Input Capture | C23: Climate zone / seasonality profile | D23: ◐ | E23: ◐ | F23: ◐ | G23: ✓ | H23: ◐ | I23: ✓ | J23: ◐ | K23: ◐ | L23: ◐ | M23: =SUMPRODUCT(--ISNUMBER(SEARCH("✓",D23:L23))) -> 2 | N23: =SUMPRODUCT(--ISNUMBER(SEARCH("◐",D23:L23))) -> 7 | O23: =SUMPRODUCT(--ISNUMBER(SEARCH("—",D23:L23))) -> 0 | P23: =9-M23-N23-O23 -> 0 | Q23: =(M23+0.5*N23)/9 -> 0.61111111 | R23: Cladwell's capsule logic is season-native.
A24: 20 | B24: B. Onboarding - Input Capture | C24: Height | D24: — | E24: ? | F24: — | G24: ✓ | H24: — | I24: ✓ | J24: ? | K24: — | L24: ? | M24: =SUMPRODUCT(--ISNUMBER(SEARCH("✓",D24:L24))) -> 2 | N24: =SUMPRODUCT(--ISNUMBER(SEARCH("◐",D24:L24))) -> 0 | O24: =SUMPRODUCT(--ISNUMBER(SEARCH("—",D24:L24))) -> 4 | P24: =9-M24-N24-O24 -> 3 | Q24: =(M24+0.5*N24)/9 -> 0.22222222
A25: 21 | B25: B. Onboarding - Input Capture | C25: Body measurements (bust/waist/hip/inseam) | D25: — | E25: ◐ | F25: — | G25: ◐ | H25: — | I25: ✓ | J25: ? | K25: — | L25: — | M25: =SUMPRODUCT(--ISNUMBER(SEARCH("✓",D25:L25))) -> 1 | N25: =SUMPRODUCT(--ISNUMBER(SEARCH("◐",D25:L25))) -> 2 | O25: =SUMPRODUCT(--ISNUMBER(SEARCH("—",D25:L25))) -> 5 | P25: =9-M25-N25-O25 -> 1 | Q25: =(M25+0.5*N25)/9 -> 0.22222222 | R25: Alta needs these for the avatar.
A26: 22 | B26: B. Onboarding - Input Capture | C26: Body shape archetype | D26: — | E26: ✓AI | F26: — | G26: ✓ | H26: — | I26: ✓ | J26: ◐ | K26: — | L26: ◐ | M26: =SUMPRODUCT(--ISNUMBER(SEARCH("✓",D26:L26))) -> 3 | N26: =SUMPRODUCT(--ISNUMBER(SEARCH("◐",D26:L26))) -> 2 | O26: =SUMPRODUCT(--ISNUMBER(SEARCH("—",D26:L26))) -> 4 | P26: =9-M26-N26-O26 -> 0 | Q26: =(M26+0.5*N26)/9 -> 0.44444444 | R26: Style DNA is the specialist - body type from a selfie.
A27: 23 | B27: B. Onboarding - Input Capture | C27: Body proportion analysis (rise, torso:leg ratio) | D27: — | E27: ◐AI | F27: — | G27: — | H27: — | I27: ✓ | J27: — | K27: — | L27: — | M27: =SUMPRODUCT(--ISNUMBER(SEARCH("✓",D27:L27))) -> 1 | N27: =SUMPRODUCT(--ISNUMBER(SEARCH("◐",D27:L27))) -> 1 | O27: =SUMPRODUCT(--ISNUMBER(SEARCH("—",D27:L27))) -> 7 | P27: =9-M27-N27-O27 -> 0 | Q27: =(M27+0.5*N27)/9 -> 0.16666667 | R27: Acloset 'fit diagnosis'; Alta silhouette modelling.
A28: 24 | B28: B. Onboarding - Input Capture | C28: Skin tone / undertone | D28: — | E28: ✓AI | F28: — | G28: ✓ | H28: — | I28: ✓ | J28: ? | K28: — | L28: — | M28: =SUMPRODUCT(--ISNUMBER(SEARCH("✓",D28:L28))) -> 3 | N28: =SUMPRODUCT(--ISNUMBER(SEARCH("◐",D28:L28))) -> 0 | O28: =SUMPRODUCT(--ISNUMBER(SEARCH("—",D28:L28))) -> 5 | P28: =9-M28-N28-O28 -> 1 | Q28: =(M28+0.5*N28)/9 -> 0.33333333 | R28: Style DNA: 12 seasonal colour types from a selfie in ~35s.
A29: 25 | B29: B. Onboarding - Input Capture | C29: Hair colour / length | D29: — | E29: ? | F29: — | G29: ◐ | H29: — | I29: ✓ | J29: ? | K29: — | L29: — | M29: =SUMPRODUCT(--ISNUMBER(SEARCH("✓",D29:L29))) -> 1 | N29: =SUMPRODUCT(--ISNUMBER(SEARCH("◐",D29:L29))) -> 1 | O29: =SUMPRODUCT(--ISNUMBER(SEARCH("—",D29:L29))) -> 5 | P29: =9-M29-N29-O29 -> 2 | Q29: =(M29+0.5*N29)/9 -> 0.16666667 | R29: Glance AI captures hair length + ethnicity at onboarding.
A30: 26 | B30: B. Onboarding - Input Capture | C30: Eye colour | D30: — | E30: ? | F30: — | G30: ◐ | H30: — | I30: ? | J30: — | K30: — | L30: — | M30: =SUMPRODUCT(--ISNUMBER(SEARCH("✓",D30:L30))) -> 0 | N30: =SUMPRODUCT(--ISNUMBER(SEARCH("◐",D30:L30))) -> 1 | O30: =SUMPRODUCT(--ISNUMBER(SEARCH("—",D30:L30))) -> 6 | P30: =9-M30-N30-O30 -> 2 | Q30: =(M30+0.5*N30)/9 -> 0.055555556 | R30: Style DNA does (colour analysis input).
A31: 27 | B31: B. Onboarding - Input Capture | C31: Lifestyle / weekly activity mix | D31: ◐ | E31: ✓ | F31: ◐ | G31: ✓ | H31: — | I31: ✓ | J31: ✓ | K31: ◐ | L31: ✓ | M31: =SUMPRODUCT(--ISNUMBER(SEARCH("✓",D31:L31))) -> 5 | N31: =SUMPRODUCT(--ISNUMBER(SEARCH("◐",D31:L31))) -> 3 | O31: =SUMPRODUCT(--ISNUMBER(SEARCH("—",D31:L31))) -> 1 | P31: =9-M31-N31-O31 -> 0 | Q31: =(M31+0.5*N31)/9 -> 0.72222222 | R31: Alta explicitly cites 'lifestyle' as a model input.
A32: 28 | B32: B. Onboarding - Input Capture | C32: Occupation | D32: ? | E32: ? | F32: ? | G32: ✓ | H32: — | I32: ✓ | J32: ✓ | K32: ? | L32: ✓ | M32: =SUMPRODUCT(--ISNUMBER(SEARCH("✓",D32:L32))) -> 4 | N32: =SUMPRODUCT(--ISNUMBER(SEARCH("◐",D32:L32))) -> 0 | O32: =SUMPRODUCT(--ISNUMBER(SEARCH("—",D32:L32))) -> 1 | P32: =9-M32-N32-O32 -> 4 | Q32: =(M32+0.5*N32)/9 -> 0.44444444
A33: 29 | B33: B. Onboarding - Input Capture | C33: Workplace dress code | D33: ◐ | E33: ◐ | F33: ◐ | G33: ✓ | H33: — | I33: ✓ | J33: ✓ | K33: ◐ | L33: ✓ | M33: =SUMPRODUCT(--ISNUMBER(SEARCH("✓",D33:L33))) -> 4 | N33: =SUMPRODUCT(--ISNUMBER(SEARCH("◐",D33:L33))) -> 4 | O33: =SUMPRODUCT(--ISNUMBER(SEARCH("—",D33:L33))) -> 1 | P33: =9-M33-N33-O33 -> 0 | Q33: =(M33+0.5*N33)/9 -> 0.66666667 | R33: Mostly captured as a tag, not as a constraint model.
A34: 30 | B34: B. Onboarding - Input Capture | C34: Style archetype / aesthetic quiz | D34: ✓ | E34: ✓ | F34: ◐ | G34: ✓ | H34: — | I34: ✓ | J34: ✓ | K34: ✓ | L34: ✓AI | M34: =SUMPRODUCT(--ISNUMBER(SEARCH("✓",D34:L34))) -> 7 | N34: =SUMPRODUCT(--ISNUMBER(SEARCH("◐",D34:L34))) -> 1 | O34: =SUMPRODUCT(--ISNUMBER(SEARCH("—",D34:L34))) -> 1 | P34: =9-M34-N34-O34 -> 0 | Q34: =(M34+0.5*N34)/9 -> 0.83333333 | R34: Cladwell's is the most structured (custom ideal closet size + signature items).
A35: 31 | B35: B. Onboarding - Input Capture | C35: Favourite colours | D35: ✓ | E35: ✓ | F35: ✓ | G35: ✓ | H35: ✓ | I35: ✓ | J35: ✓ | K35: ✓ | L35: ✓ | M35: =SUMPRODUCT(--ISNUMBER(SEARCH("✓",D35:L35))) -> 9 | N35: =SUMPRODUCT(--ISNUMBER(SEARCH("◐",D35:L35))) -> 0 | O35: =SUMPRODUCT(--ISNUMBER(SEARCH("—",D35:L35))) -> 0 | P35: =9-M35-N35-O35 -> 0 | Q35: =(M35+0.5*N35)/9 -> 1 | R35: Trivially universal.
A36: 32 | B36: B. Onboarding - Input Capture | C36: Disliked colours | D36: ◐ | E36: ◐ | F36: ◐ | G36: ◐ | H36: ◐ | I36: ? | J36: ◐ | K36: ◐ | L36: ? | M36: =SUMPRODUCT(--ISNUMBER(SEARCH("✓",D36:L36))) -> 0 | N36: =SUMPRODUCT(--ISNUMBER(SEARCH("◐",D36:L36))) -> 7 | O36: =SUMPRODUCT(--ISNUMBER(SEARCH("—",D36:L36))) -> 0 | P36: =9-M36-N36-O36 -> 2 | Q36: =(M36+0.5*N36)/9 -> 0.38888889 | R36: Weak everywhere - usually inferred, not asked.
A37: 33 | B37: B. Onboarding - Input Capture | C37: Favourite silhouettes / cuts | D37: — | E37: ◐ | F37: — | G37: ◐ | H37: — | I37: ✓ | J37: ◐ | K37: — | L37: ◐ | M37: =SUMPRODUCT(--ISNUMBER(SEARCH("✓",D37:L37))) -> 1 | N37: =SUMPRODUCT(--ISNUMBER(SEARCH("◐",D37:L37))) -> 4 | O37: =SUMPRODUCT(--ISNUMBER(SEARCH("—",D37:L37))) -> 4 | P37: =9-M37-N37-O37 -> 0 | Q37: =(M37+0.5*N37)/9 -> 0.33333333
A38: 34 | B38: B. Onboarding - Input Capture | C38: Favourite brands | D38: ✓ | E38: ✓ | F38: ✓ | G38: ✓ | H38: ✓ | I38: ✓ | J38: ✓ | K38: ✓ | L38: ◐ | M38: =SUMPRODUCT(--ISNUMBER(SEARCH("✓",D38:L38))) -> 8 | N38: =SUMPRODUCT(--ISNUMBER(SEARCH("◐",D38:L38))) -> 1 | O38: =SUMPRODUCT(--ISNUMBER(SEARCH("—",D38:L38))) -> 0 | P38: =9-M38-N38-O38 -> 0 | Q38: =(M38+0.5*N38)/9 -> 0.94444444 | R38: Stored as tags; rarely used as a taste signal.
A39: 35 | B39: B. Onboarding - Input Capture | C39: Budget / price band per category | D39: — | E39: ◐ | F39: — | G39: ◐ | H39: — | I39: ✓ | J39: ◐ | K39: ◐ | L39: — | M39: =SUMPRODUCT(--ISNUMBER(SEARCH("✓",D39:L39))) -> 1 | N39: =SUMPRODUCT(--ISNUMBER(SEARCH("◐",D39:L39))) -> 4 | O39: =SUMPRODUCT(--ISNUMBER(SEARCH("—",D39:L39))) -> 4 | P39: =9-M39-N39-O39 -> 0 | Q39: =(M39+0.5*N39)/9 -> 0.33333333 | R39: Alta is the only one treating budget as a first-class model input.
A40: 36 | B40: B. Onboarding - Input Capture | C40: Fashion goals (e.g. 'look senior at work') | D40: — | E40: ◐ | F40: ◐H | G40: ✓ | H40: — | I40: ◐ | J40: ◐ | K40: — | L40: ◐ | M40: =SUMPRODUCT(--ISNUMBER(SEARCH("✓",D40:L40))) -> 1 | N40: =SUMPRODUCT(--ISNUMBER(SEARCH("◐",D40:L40))) -> 5 | O40: =SUMPRODUCT(--ISNUMBER(SEARCH("—",D40:L40))) -> 3 | P40: =9-M40-N40-O40 -> 0 | Q40: =(M40+0.5*N40)/9 -> 0.38888889 | R40: Best served by human stylists (Indyx, Wishi, Stitch Fix).
A41: 37 | B41: B. Onboarding - Input Capture | C41: Comfort preferences (fabric, waistband, heel height) | D41: — | E41: ? | F41: — | G41: ◐ | H41: — | I41: ? | J41: ? | K41: — | L41: — | M41: =SUMPRODUCT(--ISNUMBER(SEARCH("✓",D41:L41))) -> 0 | N41: =SUMPRODUCT(--ISNUMBER(SEARCH("◐",D41:L41))) -> 1 | O41: =SUMPRODUCT(--ISNUMBER(SEARCH("—",D41:L41))) -> 5 | P41: =9-M41-N41-O41 -> 3 | Q41: =(M41+0.5*N41)/9 -> 0.055555556 | R41: NEAR-UNIVERSAL GAP.
A42: 38 | B42: B. Onboarding - Input Capture | C42: Fit preference (oversized / fitted) | D42: — | E42: ◐ | F42: — | G42: ◐ | H42: — | I42: ✓ | J42: ? | K42: — | L42: — | M42: =SUMPRODUCT(--ISNUMBER(SEARCH("✓",D42:L42))) -> 1 | N42: =SUMPRODUCT(--ISNUMBER(SEARCH("◐",D42:L42))) -> 2 | O42: =SUMPRODUCT(--ISNUMBER(SEARCH("—",D42:L42))) -> 5 | P42: =9-M42-N42-O42 -> 1 | Q42: =(M42+0.5*N42)/9 -> 0.22222222
...

Sheet 6. Coverage Summary
A1: COVERAGE SUMMARY (LIVE FORMULAS)
A2: Counts of clearly-available (✓) capabilities per product per category, pulled from Sheet 5. Nothing here is hardcoded - edit Sheet 5 and this updates.
A4: Category | B4: Capabilities mapped | C4: WHE | D4: ACL | E4: IND | F4: CLA | G4: STB | H4: ALT | I4: PRO | J4: PUR | K4: VES | L4: Nobody has it
A5: A. Discovery / Acquisition | B5: =COUNTIF('5. Feature Matrix'!$B$5:$B$386,$A5) -> 14 | C5: =SUMPRODUCT(('5. Feature Matrix'!$B$5:$B$386=$A5)*ISNUMBER(SEARCH("✓",'5. Feature Matrix'!D$5:D$386))) -> 7 | D5: =SUMPRODUCT(('5. Feature Matrix'!$B$5:$B$386=$A5)*ISNUMBER(SEARCH("✓",'5. Feature Matrix'!E$5:E$386))) -> 6 | E5: =SUMPRODUCT(('5. Feature Matrix'!$B$5:$B$386=$A5)*ISNUMBER(SEARCH("✓",'5. Feature Matrix'!F$5:F$386))) -> 7 | F5: =SUMPRODUCT(('5. Feature Matrix'!$B$5:$B$386=$A5)*ISNUMBER(SEARCH("✓",'5. Feature Matrix'!G$5:G$386))) -> 3 | G5: =SUMPRODUCT(('5. Feature Matrix'!$B$5:$B$386=$A5)*ISNUMBER(SEARCH("✓",'5. Feature Matrix'!H$5:H$386))) -> 0 | H5: =SUMPRODUCT(('5. Feature Matrix'!$B$5:$B$386=$A5)*ISNUMBER(SEARCH("✓",'5. Feature Matrix'!I$5:I$386))) -> 7 | I5: =SUMPRODUCT(('5. Feature Matrix'!$B$5:$B$386=$A5)*ISNUMBER(SEARCH("✓",'5. Feature Matrix'!J$5:J$386))) -> 6 | J5: =SUMPRODUCT(('5. Feature Matrix'!$B$5:$B$386=$A5)*ISNUMBER(SEARCH("✓",'5. Feature Matrix'!K$5:K$386))) -> 4 | K5: =SUMPRODUCT(('5. Feature Matrix'!$B$5:$B$386=$A5)*ISNUMBER(SEARCH("✓",'5. Feature Matrix'!L$5:L$386))) -> 1 | L5: =SUMPRODUCT(('5. Feature Matrix'!$B$5:$B$386=$A5)*('5. Feature Matrix'!$M$5:$M$386=0)*('5. Feature Matrix'!$N$5:$N$386=0)) -> 1
A6: B. Onboarding - Input Capture | B6: =COUNTIF('5. Feature Matrix'!$B$5:$B$386,$A6) -> 34 | C6: =SUMPRODUCT(('5. Feature Matrix'!$B$5:$B$386=$A6)*ISNUMBER(SEARCH("✓",'5. Feature Matrix'!D$5:D$386))) -> 6 | D6: =SUMPRODUCT(('5. Feature Matrix'!$B$5:$B$386=$A6)*ISNUMBER(SEARCH("✓",'5. Feature Matrix'!E$5:E$386))) -> 10 | E6: =SUMPRODUCT(('5. Feature Matrix'!$B$5:$B$386=$A6)*ISNUMBER(SEARCH("✓",'5. Feature Matrix'!F$5:F$386))) -> 4 | F6: =SUMPRODUCT(('5. Feature Matrix'!$B$5:$B$386=$A6)*ISNUMBER(SEARCH("✓",'5. Feature Matrix'!G$5:G$386))) -> 16 | G6: =SUMPRODUCT(('5. Feature Matrix'!$B$5:$B$386=$A6)*ISNUMBER(SEARCH("✓",'5. Feature Matrix'!H$5:H$386))) -> 3 | H6: =SUMPRODUCT(('5. Feature Matrix'!$B$5:$B$386=$A6)*ISNUMBER(SEARCH("✓",'5. Feature Matrix'!I$5:I$386))) -> 20 | I6: =SUMPRODUCT(('5. Feature Matrix'!$B$5:$B$386=$A6)*ISNUMBER(SEARCH("✓",'5. Feature Matrix'!J$5:J$386))) -> 12 | J6: =SUMPRODUCT(('5. Feature Matrix'!$B$5:$B$386=$A6)*ISNUMBER(SEARCH("✓",'5. Feature Matrix'!K$5:K$386))) -> 5 | K6: =SUMPRODUCT(('5. Feature Matrix'!$B$5:$B$386=$A6)*ISNUMBER(SEARCH("✓",'5. Feature Matrix'!L$5:L$386))) -> 9 | L6: =SUMPRODUCT(('5. Feature Matrix'!$B$5:$B$386=$A6)*('5. Feature Matrix'!$M$5:$M$386=0)*('5. Feature Matrix'!$N$5:$N$386=0)) -> 6
A7: C. Wardrobe Digitisation | B7: =COUNTIF('5. Feature Matrix'!$B$5:$B$386,$A7) -> 39 | C7: =SUMPRODUCT(('5. Feature Matrix'!$B$5:$B$386=$A7)*ISNUMBER(SEARCH("✓",'5. Feature Matrix'!D$5:D$386))) -> 15 | D7: =SUMPRODUCT(('5. Feature Matrix'!$B$5:$B$386=$A7)*ISNUMBER(SEARCH("✓",'5. Feature Matrix'!E$5:E$386))) -> 29 | E7: =SUMPRODUCT(('5. Feature Matrix'!$B$5:$B$386=$A7)*ISNUMBER(SEARCH("✓",'5. Feature Matrix'!F$5:F$386))) -> 18 | F7: =SUMPRODUCT(('5. Feature Matrix'!$B$5:$B$386=$A7)*ISNUMBER(SEARCH("✓",'5. Feature Matrix'!G$5:G$386))) -> 7 | G7: =SUMPRODUCT(('5. Feature Matrix'!$B$5:$B$386=$A7)*ISNUMBER(SEARCH("✓",'5. Feature Matrix'!H$5:H$386))) -> 15 | H7: =SUMPRODUCT(('5. Feature Matrix'!$B$5:$B$386=$A7)*ISNUMBER(SEARCH("✓",'5. Feature Matrix'!I$5:I$386))) -> 23 | I7: =SUMPRODUCT(('5. Feature Matrix'!$B$5:$B$386=$A7)*ISNUMBER(SEARCH("✓",'5. Feature Matrix'!J$5:J$386))) -> 22 | J7: =SUMPRODUCT(('5. Feature Matrix'!$B$5:$B$386=$A7)*ISNUMBER(SEARCH("✓",'5. Feature Matrix'!K$5:K$386))) -> 14 | K7: =SUMPRODUCT(('5. Feature Matrix'!$B$5:$B$386=$A7)*ISNUMBER(SEARCH("✓",'5. Feature Matrix'!L$5:L$386))) -> 9 | L7: =SUMPRODUCT(('5. Feature Matrix'!$B$5:$B$386=$A7)*('5. Feature Matrix'!$M$5:$M$386=0)*('5. Feature Matrix'!$N$5:$N$386=0)) -> 1
A8: D. Digital Closet | B8: =COUNTIF('5. Feature Matrix'!$B$5:$B$386,$A8) -> 29 | C8: =SUMPRODUCT(('5. Feature Matrix'!$B$5:$B$386=$A8)*ISNUMBER(SEARCH("✓",'5. Feature Matrix'!D$5:D$386))) -> 10 | D8: =SUMPRODUCT(('5. Feature Matrix'!$B$5:$B$386=$A8)*ISNUMBER(SEARCH("✓",'5. Feature Matrix'!E$5:E$386))) -> 21 | E8: =SUMPRODUCT(('5. Feature Matrix'!$B$5:$B$386=$A8)*ISNUMBER(SEARCH("✓",'5. Feature Matrix'!F$5:F$386))) -> 17 | F8: =SUMPRODUCT(('5. Feature Matrix'!$B$5:$B$386=$A8)*ISNUMBER(SEARCH("✓",'5. Feature Matrix'!G$5:G$386))) -> 10 | G8: =SUMPRODUCT(('5. Feature Matrix'!$B$5:$B$386=$A8)*ISNUMBER(SEARCH("✓",'5. Feature Matrix'!H$5:H$386))) -> 21 | H8: =SUMPRODUCT(('5. Feature Matrix'!$B$5:$B$386=$A8)*ISNUMBER(SEARCH("✓",'5. Feature Matrix'!I$5:I$386))) -> 15 | I8: =SUMPRODUCT(('5. Feature Matrix'!$B$5:$B$386=$A8)*ISNUMBER(SEARCH("✓",'5. Feature Matrix'!J$5:J$386))) -> 15 | J8: =SUMPRODUCT(('5. Feature Matrix'!$B$5:$B$386=$A8)*ISNUMBER(SEARCH("✓",'5. Feature Matrix'!K$5:K$386))) -> 18 | K8: =SUMPRODUCT(('5. Feature Matrix'!$B$5:$B$386=$A8)*ISNUMBER(SEARCH("✓",'5. Feature Matrix'!L$5:L$386))) -> 5 | L8: =SUMPRODUCT(('5. Feature Matrix'!$B$5:$B$386=$A8)*('5. Feature Matrix'!$M$5:$M$386=0)*('5. Feature Matrix'!$N$5:$N$386=0)) -> 0
A9: E1. Style Understanding - Explicit | B9: =COUNTIF('5. Feature Matrix'!$B$5:$B$386,$A9) -> 6 | C9: =SUMPRODUCT(('5. Feature Matrix'!$B$5:$B$386=$A9)*ISNUMBER(SEARCH("✓",'5. Feature Matrix'!D$5:D$386))) -> 3 | D9: =SUMPRODUCT(('5. Feature Matrix'!$B$5:$B$386=$A9)*ISNUMBER(SEARCH("✓",'5. Feature Matrix'!E$5:E$386))) -> 4 | E9: =SUMPRODUCT(('5. Feature Matrix'!$B$5:$B$386=$A9)*ISNUMBER(SEARCH("✓",'5. Feature Matrix'!F$5:F$386))) -> 1 | F9: =SUMPRODUCT(('5. Feature Matrix'!$B$5:$B$386=$A9)*ISNUMBER(SEARCH("✓",'5. Feature Matrix'!G$5:G$386))) -> 4 | G9: =SUMPRODUCT(('5. Feature Matrix'!$B$5:$B$386=$A9)*ISNUMBER(SEARCH("✓",'5. Feature Matrix'!H$5:H$386))) -> 1 | H9: =SUMPRODUCT(('5. Feature Matrix'!$B$5:$B$386=$A9)*ISNUMBER(SEARCH("✓",'5. Feature Matrix'!I$5:I$386))) -> 4 | I9: =SUMPRODUCT(('5. Feature Matrix'!$B$5:$B$386=$A9)*ISNUMBER(SEARCH("✓",'5. Feature Matrix'!J$5:J$386))) -> 4 | J9: =SUMPRODUCT(('5. Feature Matrix'!$B$5:$B$386=$A9)*ISNUMBER(SEARCH("✓",'5. Feature Matrix'!K$5:K$386))) -> 2 | K9: =SUMPRODUCT(('5. Feature Matrix'!$B$5:$B$386=$A9)*ISNUMBER(SEARCH("✓",'5. Feature Matrix'!L$5:L$386))) -> 4 | L9: =SUMPRODUCT(('5. Feature Matrix'!$B$5:$B$386=$A9)*('5. Feature Matrix'!$M$5:$M$386=0)*('5. Feature Matrix'!$N$5:$N$386=0)) -> 0
A10: E2. Style Understanding - Inferred | B10: =COUNTIF('5. Feature Matrix'!$B$5:$B$386,$A10) -> 7 | C10: =SUMPRODUCT(('5. Feature Matrix'!$B$5:$B$386=$A10)*ISNUMBER(SEARCH("✓",'5. Feature Matrix'!D$5:D$386))) -> 1 | D10: =SUMPRODUCT(('5. Feature Matrix'!$B$5:$B$386=$A10)*ISNUMBER(SEARCH("✓",'5. Feature Matrix'!E$5:E$386))) -> 5 | E10: =SUMPRODUCT(('5. Feature Matrix'!$B$5:$B$386=$A10)*ISNUMBER(SEARCH("✓",'5. Feature Matrix'!F$5:F$386))) -> 2 | F10: =SUMPRODUCT(('5. Feature Matrix'!$B$5:$B$386=$A10)*ISNUMBER(SEARCH("✓",'5. Feature Matrix'!G$5:G$386))) -> 2 | G10: =SUMPRODUCT(('5. Feature Matrix'!$B$5:$B$386=$A10)*ISNUMBER(SEARCH("✓",'5. Feature Matrix'!H$5:H$386))) -> 2 | H10: =SUMPRODUCT(('5. Feature Matrix'!$B$5:$B$386=$A10)*ISNUMBER(SEARCH("✓",'5. Feature Matrix'!I$5:I$386))) -> 5 | I10: =SUMPRODUCT(('5. Feature Matrix'!$B$5:$B$386=$A10)*ISNUMBER(SEARCH("✓",'5. Feature Matrix'!J$5:J$386))) -> 2 | J10: =SUMPRODUCT(('5. Feature Matrix'!$B$5:$B$386=$A10)*ISNUMBER(SEARCH("✓",'5. Feature Matrix'!K$5:K$386))) -> 1 | K10: =SUMPRODUCT(('5. Feature Matrix'!$B$5:$B$386=$A10)*ISNUMBER(SEARCH("✓",'5. Feature Matrix'!L$5:L$386))) -> 0 | L10: =SUMPRODUCT(('5. Feature Matrix'!$B$5:$B$386=$A10)*('5. Feature Matrix'!$M$5:$M$386=0)*('5. Feature Matrix'!$N$5:$N$386=0)) -> 1
A11: E3. Style Understanding - Behavioural | B11: =COUNTIF('5. Feature Matrix'!$B$5:$B$386,$A11) -> 11 | C11: =SUMPRODUCT(('5. Feature Matrix'!$B$5:$B$386=$A11)*ISNUMBER(SEARCH("✓",'5. Feature Matrix'!D$5:D$386))) -> 1 | D11: =SUMPRODUCT(('5. Feature Matrix'!$B$5:$B$386=$A11)*ISNUMBER(SEARCH("✓",'5. Feature Matrix'!E$5:E$386))) -> 3 | E11: =SUMPRODUCT(('5. Feature Matrix'!$B$5:$B$386=$A11)*ISNUMBER(SEARCH("✓",'5. Feature Matrix'!F$5:F$386))) -> 1 | F11: =SUMPRODUCT(('5. Feature Matrix'!$B$5:$B$386=$A11)*ISNUMBER(SEARCH("✓",'5. Feature Matrix'!G$5:G$386))) -> 2 | G11: =SUMPRODUCT(('5. Feature Matrix'!$B$5:$B$386=$A11)*ISNUMBER(SEARCH("✓",'5. Feature Matrix'!H$5:H$386))) -> 1 | H11: =SUMPRODUCT(('5. Feature Matrix'!$B$5:$B$386=$A11)*ISNUMBER(SEARCH("✓",'5. Feature Matrix'!I$5:I$386))) -> 4 | I11: =SUMPRODUCT(('5. Feature Matrix'!$B$5:$B$386=$A11)*ISNUMBER(SEARCH("✓",'5. Feature Matrix'!J$5:J$386))) -> 3 | J11: =SUMPRODUCT(('5. Feature Matrix'!$B$5:$B$386=$A11)*ISNUMBER(SEARCH("✓",'5. Feature Matrix'!K$5:K$386))) -> 1 | K11: =SUMPRODUCT(('5. Feature Matrix'!$B$5:$B$386=$A11)*ISNUMBER(SEARCH("✓",'5. Feature Matrix'!L$5:L$386))) -> 2 | L11: =SUMPRODUCT(('5. Feature Matrix'!$B$5:$B$386=$A11)*('5. Feature Matrix'!$M$5:$M$386=0)*('5. Feature Matrix'!$N$5:$N$386=0)) -> 1
A12: F1. AI Styling - Triggers & Contexts | B12: =COUNTIF('5. Feature Matrix'!$B$5:$B$386,$A12) -> 29 | C12: =SUMPRODUCT(('5. Feature Matrix'!$B$5:$B$386=$A12)*ISNUMBER(SEARCH("✓",'5. Feature Matrix'!D$5:D$386))) -> 6 | D12: =SUMPRODUCT(('5. Feature Matrix'!$B$5:$B$386=$A12)*ISNUMBER(SEARCH("✓",'5. Feature Matrix'!E$5:E$386))) -> 20 | E12: =SUMPRODUCT(('5. Feature Matrix'!$B$5:$B$386=$A12)*ISNUMBER(SEARCH("✓",'5. Feature Matrix'!F$5:F$386))) -> 2 | F12: =SUMPRODUCT(('5. Feature Matrix'!$B$5:$B$386=$A12)*ISNUMBER(SEARCH("✓",'5. Feature Matrix'!G$5:G$386))) -> 11 | G12: =SUMPRODUCT(('5. Feature Matrix'!$B$5:$B$386=$A12)*ISNUMBER(SEARCH("✓",'5. Feature Matrix'!H$5:H$386))) -> 2 | H12: =SUMPRODUCT(('5. Feature Matrix'!$B$5:$B$386=$A12)*ISNUMBER(SEARCH("✓",'5. Feature Matrix'!I$5:I$386))) -> 24 | I12: =SUMPRODUCT(('5. Feature Matrix'!$B$5:$B$386=$A12)*ISNUMBER(SEARCH("✓",'5. Feature Matrix'!J$5:J$386))) -> 19 | J12: =SUMPRODUCT(('5. Feature Matrix'!$B$5:$B$386=$A12)*ISNUMBER(SEARCH("✓",'5. Feature Matrix'!K$5:K$386))) -> 7 | K12: =SUMPRODUCT(('5. Feature Matrix'!$B$5:$B$386=$A12)*ISNUMBER(SEARCH("✓",'5. Feature Matrix'!L$5:L$386))) -> 9 | L12: =SUMPRODUCT(('5. Feature Matrix'!$B$5:$B$386=$A12)*('5. Feature Matrix'!$M$5:$M$386=0)*('5. Feature Matrix'!$N$5:$N$386=0)) -> 3
A13: F2. AI Styling - Interaction | B13: =COUNTIF('5. Feature Matrix'!$B$5:$B$386,$A13) -> 18 | C13: =SUMPRODUCT(('5. Feature Matrix'!$B$5:$B$386=$A13)*ISNUMBER(SEARCH("✓",'5. Feature Matrix'!D$5:D$386))) -> 3 | D13: =SUMPRODUCT(('5. Feature Matrix'!$B$5:$B$386=$A13)*ISNUMBER(SEARCH("✓",'5. Feature Matrix'!E$5:E$386))) -> 9 | E13: =SUMPRODUCT(('5. Feature Matrix'!$B$5:$B$386=$A13)*ISNUMBER(SEARCH("✓",'5. Feature Matrix'!F$5:F$386))) -> 1 | F13: =SUMPRODUCT(('5. Feature Matrix'!$B$5:$B$386=$A13)*ISNUMBER(SEARCH("✓",'5. Feature Matrix'!G$5:G$386))) -> 5 | G13: =SUMPRODUCT(('5. Feature Matrix'!$B$5:$B$386=$A13)*ISNUMBER(SEARCH("✓",'5. Feature Matrix'!H$5:H$386))) -> 0 | H13: =SUMPRODUCT(('5. Feature Matrix'!$B$5:$B$386=$A13)*ISNUMBER(SEARCH("✓",'5. Feature Matrix'!I$5:I$386))) -> 6 | I13: =SUMPRODUCT(('5. Feature Matrix'!$B$5:$B$386=$A13)*ISNUMBER(SEARCH("✓",'5. Feature Matrix'!J$5:J$386))) -> 11 | J13: =SUMPRODUCT(('5. Feature Matrix'!$B$5:$B$386=$A13)*ISNUMBER(SEARCH("✓",'5. Feature Matrix'!K$5:K$386))) -> 4 | K13: =SUMPRODUCT(('5. Feature Matrix'!$B$5:$B$386=$A13)*ISNUMBER(SEARCH("✓",'5. Feature Matrix'!L$5:L$386))) -> 2 | L13: =SUMPRODUCT(('5. Feature Matrix'!$B$5:$B$386=$A13)*('5. Feature Matrix'!$M$5:$M$386=0)*('5. Feature Matrix'!$N$5:$N$386=0)) -> 2
A14: G. Outfit Creation / Visualisation | B14: =COUNTIF('5. Feature Matrix'!$B$5:$B$386,$A14) -> 19 | C14: =SUMPRODUCT(('5. Feature Matrix'!$B$5:$B$386=$A14)*ISNUMBER(SEARCH("✓",'5. Feature Matrix'!D$5:D$386))) -> 7 | D14: =SUMPRODUCT(('5. Feature Matrix'!$B$5:$B$386=$A14)*ISNUMBER(SEARCH("✓",'5. Feature Matrix'!E$5:E$386))) -> 9 | E14: =SUMPRODUCT(('5. Feature Matrix'!$B$5:$B$386=$A14)*ISNUMBER(SEARCH("✓",'5. Feature Matrix'!F$5:F$386))) -> 5 | F14: =SUMPRODUCT(('5. Feature Matrix'!$B$5:$B$386=$A14)*ISNUMBER(SEARCH("✓",'5. Feature Matrix'!G$5:G$386))) -> 2 | G14: =SUMPRODUCT(('5. Feature Matrix'!$B$5:$B$386=$A14)*ISNUMBER(SEARCH("✓",'5. Feature Matrix'!H$5:H$386))) -> 7 | H14: =SUMPRODUCT(('5. Feature Matrix'!$B$5:$B$386=$A14)*ISNUMBER(SEARCH("✓",'5. Feature Matrix'!I$5:I$386))) -> 9 | I14: =SUMPRODUCT(('5. Feature Matrix'!$B$5:$B$386=$A14)*ISNUMBER(SEARCH("✓",'5. Feature Matrix'!J$5:J$386))) -> 5 | J14: =SUMPRODUCT(('5. Feature Matrix'!$B$5:$B$386=$A14)*ISNUMBER(SEARCH("✓",'5. Feature Matrix'!K$5:K$386))) -> 8 | K14: =SUMPRODUCT(('5. Feature Matrix'!$B$5:$B$386=$A14)*ISNUMBER(SEARCH("✓",'5. Feature Matrix'!L$5:L$386))) -> 2 | L14: =SUMPRODUCT(('5. Feature Matrix'!$B$5:$B$386=$A14)*('5. Feature Matrix'!$M$5:$M$386=0)*('5. Feature Matrix'!$N$5:$N$386=0)) -> 2
A15: H. Outfit Planning | B15: =COUNTIF('5. Feature Matrix'!$B$5:$B$386,$A15) -> 21 | C15: =SUMPRODUCT(('5. Feature Matrix'!$B$5:$B$386=$A15)*ISNUMBER(SEARCH("✓",'5. Feature Matrix'!D$5:D$386))) -> 11 | D15: =SUMPRODUCT(('5. Feature Matrix'!$B$5:$B$386=$A15)*ISNUMBER(SEARCH("✓",'5. Feature Matrix'!E$5:E$386))) -> 12 | E15: =SUMPRODUCT(('5. Feature Matrix'!$B$5:$B$386=$A15)*ISNUMBER(SEARCH("✓",'5. Feature Matrix'!F$5:F$386))) -> 9 | F15: =SUMPRODUCT(('5. Feature Matrix'!$B$5:$B$386=$A15)*ISNUMBER(SEARCH("✓",'5. Feature Matrix'!G$5:G$386))) -> 14 | G15: =SUMPRODUCT(('5. Feature Matrix'!$B$5:$B$386=$A15)*ISNUMBER(SEARCH("✓",'5. Feature Matrix'!H$5:H$386))) -> 9 | H15: =SUMPRODUCT(('5. Feature Matrix'!$B$5:$B$386=$A15)*ISNUMBER(SEARCH("✓",'5. Feature Matrix'!I$5:I$386))) -> 12 | I15: =SUMPRODUCT(('5. Feature Matrix'!$B$5:$B$386=$A15)*ISNUMBER(SEARCH("✓",'5. Feature Matrix'!J$5:J$386))) -> 13 | J15: =SUMPRODUCT(('5. Feature Matrix'!$B$5:$B$386=$A15)*ISNUMBER(SEARCH("✓",'5. Feature Matrix'!K$5:K$386))) -> 11 | K15: =SUMPRODUCT(('5. Feature Matrix'!$B$5:$B$386=$A15)*ISNUMBER(SEARCH("✓",'5. Feature Matrix'!L$5:L$386))) -> 6 | L15: =SUMPRODUCT(('5. Feature Matrix'!$B$5:$B$386=$A15)*('5. Feature Matrix'!$M$5:$M$386=0)*('5. Feature Matrix'!$N$5:$N$386=0)) -> 3
A16: I. Shopping | B16: =COUNTIF('5. Feature Matrix'!$B$5:$B$386,$A16) -> 19 | C16: =SUMPRODUCT(('5. Feature Matrix'!$B$5:$B$386=$A16)*ISNUMBER(SEARCH("✓",'5. Feature Matrix'!D$5:D$386))) -> 5 | D16: =SUMPRODUCT(('5. Feature Matrix'!$B$5:$B$386=$A16)*ISNUMBER(SEARCH("✓",'5. Feature Matrix'!E$5:E$386))) -> 9 | E16: =SUMPRODUCT(('5. Feature Matrix'!$B$5:$B$386=$A16)*ISNUMBER(SEARCH("✓",'5. Feature Matrix'!F$5:F$386))) -> 2 | F16: =SUMPRODUCT(('5. Feature Matrix'!$B$5:$B$386=$A16)*ISNUMBER(SEARCH("✓",'5. Feature Matrix'!G$5:G$386))) -> 3 | G16: =SUMPRODUCT(('5. Feature Matrix'!$B$5:$B$386=$A16)*ISNUMBER(SEARCH("✓",'5. Feature Matrix'!H$5:H$386))) -> 2 | H16: =SUMPRODUCT(('5. Feature Matrix'!$B$5:$B$386=$A16)*ISNUMBER(SEARCH("✓",'5. Feature Matrix'!I$5:I$386))) -> 13 | I16: =SUMPRODUCT(('5. Feature Matrix'!$B$5:$B$386=$A16)*ISNUMBER(SEARCH("✓",'5. Feature Matrix'!J$5:J$386))) -> 8 | J16: =SUMPRODUCT(('5. Feature Matrix'!$B$5:$B$386=$A16)*ISNUMBER(SEARCH("✓",'5. Feature Matrix'!K$5:K$386))) -> 7 | K16: =SUMPRODUCT(('5. Feature Matrix'!$B$5:$B$386=$A16)*ISNUMBER(SEARCH("✓",'5. Feature Matrix'!L$5:L$386))) -> 0 | L16: =SUMPRODUCT(('5. Feature Matrix'!$B$5:$B$386=$A16)*('5. Feature Matrix'!$M$5:$M$386=0)*('5. Feature Matrix'!$N$5:$N$386=0)) -> 1
... A31: Y. Content & Education [ADDED] | B31: =COUNTIF('5. Feature Matrix'!$B$5:$B$386,$A31) -> 4 | C31: =SUMPRODUCT(('5. Feature Matrix'!$B$5:$B$386=$A31)*ISNUMBER(SEARCH("✓",'5. Feature Matrix'!D$5:D$386))) -> 0 | D31: =SUMPRODUCT(('5. Feature Matrix'!$B$5:$B$386=$A31)*ISNUMBER(SEARCH("✓",'5. Feature Matrix'!E$5:E$386))) -> 2 | E31: =SUMPRODUCT(('5. Feature Matrix'!$B$5:$B$386=$A31)*ISNUMBER(SEARCH("✓",'5. Feature Matrix'!F$5:F$386))) -> 0 | F31: =SUMPRODUCT(('5. Feature Matrix'!$B$5:$B$386=$A31)*ISNUMBER(SEARCH("✓",'5. Feature Matrix'!G$5:G$386))) -> 2 | G31: =SUMPRODUCT(('5. Feature Matrix'!$B$5:$B$386=$A31)*ISNUMBER(SEARCH("✓",'5. Feature Matrix'!H$5:H$386))) -> 0 | H31: =SUMPRODUCT(('5. Feature Matrix'!$B$5:$B$386=$A31)*ISNUMBER(SEARCH("✓",'5. Feature Matrix'!I$5:I$386))) -> 2 | I31: =SUMPRODUCT(('5. Feature Matrix'!$B$5:$B$386=$A31)*ISNUMBER(SEARCH("✓",'5. Feature Matrix'!J$5:J$386))) -> 2 | J31: =SUMPRODUCT(('5. Feature Matrix'!$B$5:$B$386=$A31)*ISNUMBER(SEARCH("✓",'5. Feature Matrix'!K$5:K$386))) -> 0 | K31: =SUMPRODUCT(('5. Feature Matrix'!$B$5:$B$386=$A31)*ISNUMBER(SEARCH("✓",'5. Feature Matrix'!L$5:L$386))) -> 0 | L31: =SUMPRODUCT(('5. Feature Matrix'!$B$5:$B$386=$A31)*('5. Feature Matrix'!$M$5:$M$386=0)*('5. Feature Matrix'!$N$5:$N$386=0)) -> 0
A32: TOTAL | B32: =SUM(B5:B31) -> 382 | C32: =SUM(C5:C31) -> 105 | D32: =SUM(D5:D31) -> 186 | E32: =SUM(E5:E31) -> 104 | F32: =SUM(F5:F31) -> 103 | G32: =SUM(G5:G31) -> 84 | H32: =SUM(H5:H31) -> 172 | I32: =SUM(I5:I31) -> 149 | ... L32: =SUM(L5:L31) -> 52
A33: % of all mapped capabilities clearly available | C33: =C32/$B$32 -> 0.27486911 | D33: =D32/$B$32 -> 0.48691099 | E33: =E32/$B$32 -> 0.27225131 | F33: =F32/$B$32 -> 0.26963351 | G33: =G32/$B$32 -> 0.21989529 | H33: =H32/$B$32 -> 0.45026178 | I33: =I32/$B$32 -> 0.39005236 | J33: =J32/$B$32 -> 0.26963351 | K33: =K32/$B$32 -> 0.15183246
A35: APP CODES
C36: Whering | D36: Acloset | E36: Indyx | F36: Cladwell | G36: Stylebook | H36: Alta | I36: Pronti | J36: Pureple | K36: Vesta Wardrobe
A38: HOW TO USE THIS SHEET
A39: • 'Capabilities mapped' = how many rows exist in that category on Sheet 5.
A40: • Product columns count only clearly-available (✓) marks. Partial (◐) and unclear (?) are NOT counted here - see the per-row Coverage % on Sheet 5 for a weighted view.
A41: • 'Nobody has it' counts rows where no product scores ✓ or ◐. These are the theoretical-universe gaps and the most strategically useful cells in the workbook.
A42: • A HIGH SCORE IS NOT A VERDICT. Breadth of claimed features is not product quality, and this workbook contains no quality verification. Feature count says nothing about whether the AI is any good.
A43: • Indyx will under-score on styling categories BY DESIGN - it deliberately has no AI generation and sells human stylists instead. Stylebook will under-score across the board for the same kind of reason: it is a manual tool by choice, with a one-time price.

Sheet 7. Sophistication Scores
A1: SOPHISTICATION / DEPTH ASSESSMENT
A2: 1 = basic | 2 = moderate | 3 = sophisticated | 4 = highly differentiated | ? = insufficient information | n/a = not attempted. Only for features where 'the feature exists' and 'the feature is good' diverge most.
A4: Major capability | B4: WHE | C4: ACL | D4: IND | E4: CLA | F4: STB | G4: ALT | H4: PRO | I4: PUR | J4: VES | K4: Category ceiling today
A5: Wardrobe ingestion (speed to a usable closet) | B5: 2 | C5: 4 | D5: 3* | E5: 2 | F5: 1 | G5: 3 | H5: 3 | I5: 2 | J5: 1 | K5: 4 (Acloset: Gmail + multi-item photo). *Indyx scores 3 only via a HUMAN service
A6: Auto-tagging accuracy and depth | B6: 2 | C6: 3 | D6: 2 | E6: 1 | F6: n/a | G6: 3? | H6: 2 | I6: 2 | J6: 1 | K6: 3 - nobody is at 4
A7: Outfit generation quality | B7: 2 | C7: 2 | D7: n/a | E7: 2 | F7: n/a | G7: 3? | H7: 3 | I7: 2 | J7: 1 | K7: 3, and only Alta / Pronti plausibly
A8: Context awareness (weather / occasion / calendar) | B8: 2 | C8: 3 | D8: 1 | E8: 2 | F8: 1 | G8: 4? | H8: 3 | I8: 2 | J8: 2 | K8: 4 claimed by Alta, unverified
A9: Behavioural learning | B9: ? | C9: 2? | D9: n/a | E9: 2 | F9: n/a | G9: 3? | H9: 2? | I9: ? | J9: 1 | K9: GENUINELY UNCERTAIN - nobody has demonstrated 3+
A10: Body / colour personalisation | B10: 1 | C10: 3 | D10: 3H | E10: 2 | F10: 1 | G10: 4 | H10: 2 | I10: 1 | J10: 2 | K10: Style DNA scores 4 in its narrow domain
A11: Visualisation / virtual try-on | B11: 1 | C11: 3 | D11: 2 | E11: 1 | F11: 2 | G11: 4 | H11: 2 | I11: 3 | J11: 1 | K11: 4 (Alta, Glance AI, Stitch Fix Vision)
A12: Outfit collage / creation tooling | B12: 3 | C12: 3 | D12: 4 | E12: 1 | F12: 4 | G12: 2 | H12: 3 | I12: 3 | J12: 2 | K12: 4 (Stylebook, Indyx, Combyne)
A13: Planning and calendar | B13: 3 | C13: 3 | D13: 4 | E13: 3 | F13: 4 | G13: 3 | H13: 3 | I13: 3 | J13: 2 | K13: 4
A14: Packing and travel | B14: 3 | C14: 3 | D14: 3 | E14: 4 | F14: 3 | G14: 3 | H14: 3 | I14: 3 | J14: 1 | K14: 4 (Cladwell travel capsule)
A15: Analytics depth | B15: 3 | C15: 3 | D15: 4 | E15: 2 | F15: 4 | G15: 3 | H15: 2 | I15: 2 | J15: 2 | K15: 4 (Stylebook, Indyx)
... A22: Explainability | B22: 1 | C22: 2 | D22: 3H | E22: 2 | F22: n/a | G22: 2 | H22: 2 | I22: 2 | J22: 1 | K22: 3, and only via a HUMAN

Sheet 8. AI Intelligence Layer
A1: AI / INTELLIGENCE LAYER - WHAT IS ACTUALLY UNDER THE HOOD
A2: Separated from the marketing label. Do NOT assume something marketed as 'AI' is sophisticated AI.
A4: Product | B4: Rules / heuristics | C4: Templates | D4: Computer vision | E4: Classical recsys | F4: ML on behaviour | G4: LLM | H4: GenAI imagery | I4: Multimodal | J4: Human | K4: Assessment | L4: Confidence
A5: Whering | B5: High | C5: Yes | D5: Yes (bg removal, tagging ~50% acc.) | E5: Partial | F5: ? | G5: Partial | H5: Partial (Enhance) | I5: Partial | J5: No | K5: 'Shuffle' reads as CONSTRAINED RANDOMISATION + weather filter, not a learned model. Google AI Futures money is explicitly to change this | L5: Medium
A6: Acloset | B6: Yes | C6: Yes | D6: STRONG (multi-item extraction, colour + fit analysis) | E6: Yes | F6: Partial | G6: Yes (Style Chat) | H6: Yes (beautify, try-on) | I6: Yes | J6: No | K6: DEEPEST CV STACK in the direct set. Reviews report recommendation quality lagging ingestion quality | L6: Medium-High
A7: Indyx | B7: Yes | C7: Yes | D7: Yes (bg removal, auto-tag) | E7: No | F7: No | G7: No | H7: No | I7: No | J7: STRONG | K7: DELIBERATELY NOT AN AI PRODUCT. AI used only for ingestion; styling is human/manual | L7: High
A8: Cladwell | B8: Strong | C8: Strong (wardrobe templates) | D8: Partial | E8: Partial | F8: Partial | G8: Yes (Ask Cladwell = ChatGPT) | H8: No | I8: No | J8: No | K8: Core engine looks RULE/TEMPLATE-BASED; the LLM is a bolt-on advice surface. 97F -> boots reports support this | L8: Medium-High
A9: Stylebook | B9: Partial | C9: No | D9: No | E9: No | F9: No | G9: No | H9: No | I9: No | J9: No | K9: NO AI. OPENLY. Pure database + manual tooling | L9: High
A10: Alta | B10: Yes | C10: No | D10: Yes | E10: Yes | F10: Yes? | G10: Yes | H10: STRONG (avatar try-on) | I10: Yes | J10: Partial (training) | K10: Claims a dozen-plus in-house fashion-specific generative models. MOST CREDIBLE DEEP-AI CLAIM in the category - but unverified independently | L10: Medium
A11: Pronti | B11: Yes | C11: Yes | D11: Yes | E11: Partial | F11: Partial | G11: Yes ('PAI', closet-grounded) | H11: Partial | I11: Partial | J11: No | K11: Explicitly RETRIEVAL-GROUNDED CHAT over the user's own items - architecturally the most interesting small-team approach | L11: Medium
A12: Pureple | B12: Yes | C12: Yes | D12: Yes | E12: Partial | F12: ? | G12: Partial | H12: Yes (model try-on) | I12: Partial | J12: No | K12: Long-lived rules engine with a recent genAI layer | L12: Medium
A13: Vesta | B13: Yes | C13: Yes | D13: Yes | E13: ? | F13: ? | G13: Partial | H13: No | I13: Partial | J13: No | K13: Reviewers describe it as a RANDOMISER THAT IGNORES ONBOARDING INPUTS. Treat the 'AI' claim sceptically | L13: Low-Medium
A14: GetWardrobe | B14: Yes | C14: Yes | D14: Yes | E14: Partial | F14: ? | G14: Partial | H14: Partial | I14: Partial | J14: No | K14: 'AI Studio' + batch generator (10/run) suggests COMBINATORIAL GENERATION WITH FILTERS | L14: Low-Medium
A15: Style DNA | B15: Strong | C15: Strong | D15: Yes (selfie colour / body) | E15: Yes | F15: Partial | G15: Partial | H15: No | I15: Partial | J15: Partial (consultant-authored rules) | K15: EXPERT-SYSTEM ARCHITECTURE: codified image-consulting rules + CV feature extraction. Sophisticated WITHIN A NARROW DOMAIN | L15: Medium
... A17: Stitch Fix | B17: Yes | C17: Yes | D17: Yes | E17: STRONG | F17: STRONG | G17: Yes | H17: Yes | I17: Yes | J17: STRONG | K17: DEEPEST GENUINE HYBRID. A decade of labelled human-stylist decisions is the moat | L17: High
A19: THE HONEST READ ON 'AI' IN THIS CATEGORY:
A21: 1. COMPUTER VISION FOR INGESTION IS REAL AND COMMODITISED. Background removal and coarse category/colour tagging work.
A22: Accuracy on style, material and pattern is poor - a Whering user's estimate of ~50% correct on style/colour is
A23: consistent with what independent reviews report across the field.
A25: 2. GENERATIVE IMAGERY IS REAL AND RAPIDLY COMMODITISING. Avatar try-on went from Alta's differentiator (mid-2025) to a
A26: checkbox in tiny clone apps (2026), with Google having launched AND KILLED a standalone app in the same window.
A28: 3. STYLING JUDGEMENT IS LARGELY NOT AI. The dominant pattern is: filter the wardrobe by category and season -> apply a
A29: colour-compatibility heuristic -> randomise -> present. LLMs are typically bolted on as a CHAT SURFACE rather than
A30: being the recommender. The recurring user complaint - 'it feels like a randomiser' - is a technically accurate
A31: description of most implementations.
A33: 4. THE ONE THING NOBODY HAS: a learned model of an individual's taste from behaviour at scale. Every product claims it.
A34: No product documents it, exposes it, or demonstrates it. Stitch Fix is the closest, and it needed a decade of
A35: human-stylist labels to get there.

Sheet 9. Table Stakes vs Diff.
A1: TABLE STAKES vs DIFFERENTIATORS vs EMERGING
A2: Derived from observed prevalence across the researched set, not from intuition. Filterable by Classification.
A4: Classification | B4: Group | C4: Capability | D4: Who has it / evidence | E4: Why it sits here
A5: TABLE STAKES | B5: Digitisation | C5: Photograph + camera-roll upload; bulk upload | D5: All 9 | E5: Present in the large majority; absence is a credibility problem
A6: TABLE STAKES | B6: Digitisation | C6: Automatic background removal | D6: All except Stylebook | E6: Only Stylebook lacks it, and it is the single most-cited reason its setup is called a 6-8 hour job
A7: TABLE STAKES | B7: Digitisation | C7: Automatic category and colour tagging | D7: All except Stylebook | E7: Commodity CV
A8: TABLE STAKES | B8: Digitisation | C8: Manual override of every AI-assigned attribute | D8: All | E8: Necessary because tagging accuracy is ~50%
A9: TABLE STAKES | B9: Digitisation | C9: Add item from a product URL / share sheet | D9: All except Vesta | E9: Vesta's lack of this is called out directly in reviews
A10: TABLE STAKES | B10: Closet | C10: Filter and sort by category, colour, brand, season, occasion | D10: All | E10: Baseline
A11: TABLE STAKES | B11: Closet | C11: Custom tags; archive / off-season | D11: All | E11: Baseline
A12: TABLE STAKES | B12: Closet | C12: Cross-device sync | D12: All (Pureple paywalls it; Stylebook is device-local) | E12: Baseline
A13: TABLE STAKES | B13: Styling & planning | C13: Outfit builder (manual) | D13: All | E13: Baseline
A14: TABLE STAKES | B14: Styling & planning | C14: Generate outfit combinations from owned items | D14: All except Indyx (deliberate) | E14: Baseline
